<?xml version="1.0"?>
<robot name="differential_wheel" xmlns:xacro="http://www.ros.org/wiki/xacro">

  <xacro:macro name="differential_wheel" params="*origin wheel_prefix 
  wheel_radius wheel_length">

  <xacro:property name="M_PI" value="3.1415926535897931" />
  <xacro:property name="w_rad" value="${wheel_radius}"/>
  <xacro:property name="w_len" value="${wheel_length}"/>

  <link name="${wheel_prefix}_wheel">
    <inertial>
      <mass value="5.00"/>
      <origin xyz="0 0 0" rpy="0 ${M_PI/2} ${M_PI/2}"/>
        <inertia  ixx="0.1" ixy="0.0" ixz="0.0" iyx="0.0" iyy="0.1" 
                  iyz="0.0" izx="0.0" izy="0.0" izz="0.1" />
    </inertial>
    <visual>
      <origin xyz="0 0 0" rpy="0 ${M_PI/2} ${M_PI/2}"/>
      <geometry>
        <cylinder length="${w_len}" radius="${w_rad}"/>
      </geometry>
    </visual>
    <collision>
      <origin xyz="0 0 0" rpy="0 ${M_PI/2} ${M_PI/2}"/>
      <geometry>
        <cylinder length="${w_len}" radius="${w_rad}"/>
      </geometry>
    </collision>
  </link>
  <gazebo reference="${wheel_prefix}_wheel">
    <material>Gazebo/Red</material>
  </gazebo>
  <joint name="${wheel_prefix}_wheel_hinge" type="continuous">
    <parent link="chassis" />
    <child link="${wheel_prefix}_wheel" />
    <xacro:insert_block name="origin"/>
    <axis xyz="0 1 0" rpy="0 0 0"/>
    <limit effort="10000" velocity="1000"/>
    <dynamics damping="1.0" friction="1.0"/>  
  </joint>
  
</xacro:macro>
</robot>
